2023-08-21T18:02:53,760 Created temporary directory: C:\Users\Ayobami\AppData\Local\Temp\pip-ephem-wheel-cache-7la43_j4
2023-08-21T18:02:53,762 Created temporary directory: C:\Users\Ayobami\AppData\Local\Temp\pip-build-tracker-r1t813hu
2023-08-21T18:02:53,762 Initialized build tracking at C:\Users\Ayobami\AppData\Local\Temp\pip-build-tracker-r1t813hu
2023-08-21T18:02:53,762 Created build tracker: C:\Users\Ayobami\AppData\Local\Temp\pip-build-tracker-r1t813hu
2023-08-21T18:02:53,762 Entered build tracker: C:\Users\Ayobami\AppData\Local\Temp\pip-build-tracker-r1t813hu
2023-08-21T18:02:53,763 Created temporary directory: C:\Users\Ayobami\AppData\Local\Temp\pip-wheel-67krym_e
2023-08-21T18:02:53,765 Created temporary directory: C:\Users\Ayobami\AppData\Local\Temp\pip-ephem-wheel-cache-0gxa_h11
2023-08-21T18:02:53,788 1 location(s) to search for versions of keras:
2023-08-21T18:02:53,788 * https://pypi.org/simple/keras/
2023-08-21T18:02:53,788 Fetching project page and analyzing links: https://pypi.org/simple/keras/
2023-08-21T18:02:53,789 Getting page https://pypi.org/simple/keras/
2023-08-21T18:02:53,789 Found index url https://pypi.org/simple
2023-08-21T18:02:53,798 WARNING: Retrying (Retry(total=4, connect=None, read=None, redirect=None, status=None)) after connection broken by 'NewConnectionError('<pip._vendor.urllib3.connection.HTTPSConnection object at 0x00000149CB450888>: Failed to establish a new connection: [Errno 11001] getaddrinfo failed')': /simple/keras/
2023-08-21T18:02:54,302 WARNING: Retrying (Retry(total=3, connect=None, read=None, redirect=None, status=None)) after connection broken by 'NewConnectionError('<pip._vendor.urllib3.connection.HTTPSConnection object at 0x00000149CB452888>: Failed to establish a new connection: [Errno 11001] getaddrinfo failed')': /simple/keras/
2023-08-21T18:02:55,315 WARNING: Retrying (Retry(total=2, connect=None, read=None, redirect=None, status=None)) after connection broken by 'NewConnectionError('<pip._vendor.urllib3.connection.HTTPSConnection object at 0x00000149CB452248>: Failed to establish a new connection: [Errno 11001] getaddrinfo failed')': /simple/keras/
2023-08-21T18:02:57,338 WARNING: Retrying (Retry(total=1, connect=None, read=None, redirect=None, status=None)) after connection broken by 'NewConnectionError('<pip._vendor.urllib3.connection.HTTPSConnection object at 0x00000149CB454FC8>: Failed to establish a new connection: [Errno 11001] getaddrinfo failed')': /simple/keras/
2023-08-21T18:02:59,453 ERROR: Operation cancelled by user
2023-08-21T18:02:59,457 Exception information:
2023-08-21T18:02:59,457 Traceback (most recent call last):
2023-08-21T18:02:59,457   File "C:\Users\Ayobami\anaconda3\envs\new-mask-tut\lib\site-packages\pip\_vendor\urllib3\connection.py", line 175, in _new_conn
2023-08-21T18:02:59,457     (self._dns_host, self.port), self.timeout, **extra_kw
2023-08-21T18:02:59,457   File "C:\Users\Ayobami\anaconda3\envs\new-mask-tut\lib\site-packages\pip\_vendor\urllib3\util\connection.py", line 72, in create_connection
2023-08-21T18:02:59,457     for res in socket.getaddrinfo(host, port, family, socket.SOCK_STREAM):
2023-08-21T18:02:59,457   File "C:\Users\Ayobami\anaconda3\envs\new-mask-tut\lib\socket.py", line 752, in getaddrinfo
2023-08-21T18:02:59,457     for res in _socket.getaddrinfo(host, port, family, type, proto, flags):
2023-08-21T18:02:59,457 socket.gaierror: [Errno 11001] getaddrinfo failed
2023-08-21T18:02:59,457 
2023-08-21T18:02:59,457 During handling of the above exception, another exception occurred:
2023-08-21T18:02:59,457 
2023-08-21T18:02:59,457 Traceback (most recent call last):
2023-08-21T18:02:59,457   File "C:\Users\Ayobami\anaconda3\envs\new-mask-tut\lib\site-packages\pip\_vendor\urllib3\connectionpool.py", line 710, in urlopen
2023-08-21T18:02:59,457     chunked=chunked,
2023-08-21T18:02:59,457   File "C:\Users\Ayobami\anaconda3\envs\new-mask-tut\lib\site-packages\pip\_vendor\urllib3\connectionpool.py", line 386, in _make_request
2023-08-21T18:02:59,457     self._validate_conn(conn)
2023-08-21T18:02:59,457   File "C:\Users\Ayobami\anaconda3\envs\new-mask-tut\lib\site-packages\pip\_vendor\urllib3\connectionpool.py", line 1042, in _validate_conn
2023-08-21T18:02:59,457     conn.connect()
2023-08-21T18:02:59,457   File "C:\Users\Ayobami\anaconda3\envs\new-mask-tut\lib\site-packages\pip\_vendor\urllib3\connection.py", line 358, in connect
2023-08-21T18:02:59,457     self.sock = conn = self._new_conn()
2023-08-21T18:02:59,457   File "C:\Users\Ayobami\anaconda3\envs\new-mask-tut\lib\site-packages\pip\_vendor\urllib3\connection.py", line 187, in _new_conn
2023-08-21T18:02:59,457     self, "Failed to establish a new connection: %s" % e
2023-08-21T18:02:59,457 pip._vendor.urllib3.exceptions.NewConnectionError: <pip._vendor.urllib3.connection.HTTPSConnection object at 0x00000149CB454688>: Failed to establish a new connection: [Errno 11001] getaddrinfo failed
2023-08-21T18:02:59,457 
2023-08-21T18:02:59,457 During handling of the above exception, another exception occurred:
2023-08-21T18:02:59,457 
2023-08-21T18:02:59,457 Traceback (most recent call last):
2023-08-21T18:02:59,457   File "C:\Users\Ayobami\anaconda3\envs\new-mask-tut\lib\site-packages\pip\_internal\cli\base_command.py", line 160, in exc_logging_wrapper
2023-08-21T18:02:59,457     status = run_func(*args)
2023-08-21T18:02:59,457   File "C:\Users\Ayobami\anaconda3\envs\new-mask-tut\lib\site-packages\pip\_internal\cli\req_command.py", line 247, in wrapper
2023-08-21T18:02:59,457     return func(self, options, args)
2023-08-21T18:02:59,457   File "C:\Users\Ayobami\anaconda3\envs\new-mask-tut\lib\site-packages\pip\_internal\commands\wheel.py", line 170, in run
2023-08-21T18:02:59,457     requirement_set = resolver.resolve(reqs, check_supported_wheels=True)
2023-08-21T18:02:59,457   File "C:\Users\Ayobami\anaconda3\envs\new-mask-tut\lib\site-packages\pip\_internal\resolution\resolvelib\resolver.py", line 93, in resolve
2023-08-21T18:02:59,457     collected.requirements, max_rounds=try_to_avoid_resolution_too_deep
2023-08-21T18:02:59,457   File "C:\Users\Ayobami\anaconda3\envs\new-mask-tut\lib\site-packages\pip\_vendor\resolvelib\resolvers.py", line 481, in resolve
2023-08-21T18:02:59,457     state = resolution.resolve(requirements, max_rounds=max_rounds)
2023-08-21T18:02:59,457   File "C:\Users\Ayobami\anaconda3\envs\new-mask-tut\lib\site-packages\pip\_vendor\resolvelib\resolvers.py", line 348, in resolve
2023-08-21T18:02:59,457     self._add_to_criteria(self.state.criteria, r, parent=None)
2023-08-21T18:02:59,457   File "C:\Users\Ayobami\anaconda3\envs\new-mask-tut\lib\site-packages\pip\_vendor\resolvelib\resolvers.py", line 172, in _add_to_criteria
2023-08-21T18:02:59,457     if not criterion.candidates:
2023-08-21T18:02:59,457   File "C:\Users\Ayobami\anaconda3\envs\new-mask-tut\lib\site-packages\pip\_vendor\resolvelib\structs.py", line 151, in __bool__
2023-08-21T18:02:59,457     return bool(self._sequence)
2023-08-21T18:02:59,457   File "C:\Users\Ayobami\anaconda3\envs\new-mask-tut\lib\site-packages\pip\_internal\resolution\resolvelib\found_candidates.py", line 155, in __bool__
2023-08-21T18:02:59,457     return any(self)
2023-08-21T18:02:59,457   File "C:\Users\Ayobami\anaconda3\envs\new-mask-tut\lib\site-packages\pip\_internal\resolution\resolvelib\found_candidates.py", line 143, in <genexpr>
2023-08-21T18:02:59,457     return (c for c in iterator if id(c) not in self._incompatible_ids)
2023-08-21T18:02:59,457   File "C:\Users\Ayobami\anaconda3\envs\new-mask-tut\lib\site-packages\pip\_internal\resolution\resolvelib\found_candidates.py", line 44, in _iter_built
2023-08-21T18:02:59,457     for version, func in infos:
2023-08-21T18:02:59,457   File "C:\Users\Ayobami\anaconda3\envs\new-mask-tut\lib\site-packages\pip\_internal\resolution\resolvelib\factory.py", line 282, in iter_index_candidate_infos
2023-08-21T18:02:59,457     hashes=hashes,
2023-08-21T18:02:59,457   File "C:\Users\Ayobami\anaconda3\envs\new-mask-tut\lib\site-packages\pip\_internal\index\package_finder.py", line 889, in find_best_candidate
2023-08-21T18:02:59,457     candidates = self.find_all_candidates(project_name)
2023-08-21T18:02:59,457   File "C:\Users\Ayobami\anaconda3\envs\new-mask-tut\lib\site-packages\pip\_internal\index\package_finder.py", line 830, in find_all_candidates
2023-08-21T18:02:59,457     page_candidates = list(page_candidates_it)
2023-08-21T18:02:59,457   File "C:\Users\Ayobami\anaconda3\envs\new-mask-tut\lib\site-packages\pip\_internal\index\sources.py", line 134, in page_candidates
2023-08-21T18:02:59,457     yield from self._candidates_from_page(self._link)
2023-08-21T18:02:59,457   File "C:\Users\Ayobami\anaconda3\envs\new-mask-tut\lib\site-packages\pip\_internal\index\package_finder.py", line 790, in process_project_url
2023-08-21T18:02:59,457     index_response = self._link_collector.fetch_response(project_url)
2023-08-21T18:02:59,457   File "C:\Users\Ayobami\anaconda3\envs\new-mask-tut\lib\site-packages\pip\_internal\index\collector.py", line 461, in fetch_response
2023-08-21T18:02:59,457     return _get_index_content(location, session=self.session)
2023-08-21T18:02:59,457   File "C:\Users\Ayobami\anaconda3\envs\new-mask-tut\lib\site-packages\pip\_internal\index\collector.py", line 364, in _get_index_content
2023-08-21T18:02:59,457     resp = _get_simple_response(url, session=session)
2023-08-21T18:02:59,457   File "C:\Users\Ayobami\anaconda3\envs\new-mask-tut\lib\site-packages\pip\_internal\index\collector.py", line 158, in _get_simple_response
2023-08-21T18:02:59,457     "Cache-Control": "max-age=0",
2023-08-21T18:02:59,457   File "C:\Users\Ayobami\anaconda3\envs\new-mask-tut\lib\site-packages\pip\_vendor\requests\sessions.py", line 600, in get
2023-08-21T18:02:59,457     return self.request("GET", url, **kwargs)
2023-08-21T18:02:59,457   File "C:\Users\Ayobami\anaconda3\envs\new-mask-tut\lib\site-packages\pip\_internal\network\session.py", line 518, in request
2023-08-21T18:02:59,457     return super().request(method, url, *args, **kwargs)
2023-08-21T18:02:59,457   File "C:\Users\Ayobami\anaconda3\envs\new-mask-tut\lib\site-packages\pip\_vendor\requests\sessions.py", line 587, in request
2023-08-21T18:02:59,457     resp = self.send(prep, **send_kwargs)
2023-08-21T18:02:59,457   File "C:\Users\Ayobami\anaconda3\envs\new-mask-tut\lib\site-packages\pip\_vendor\requests\sessions.py", line 701, in send
2023-08-21T18:02:59,457     r = adapter.send(request, **kwargs)
2023-08-21T18:02:59,457   File "C:\Users\Ayobami\anaconda3\envs\new-mask-tut\lib\site-packages\pip\_vendor\cachecontrol\adapter.py", line 57, in send
2023-08-21T18:02:59,457     resp = super(CacheControlAdapter, self).send(request, **kw)
2023-08-21T18:02:59,457   File "C:\Users\Ayobami\anaconda3\envs\new-mask-tut\lib\site-packages\pip\_vendor\requests\adapters.py", line 499, in send
2023-08-21T18:02:59,457     timeout=timeout,
2023-08-21T18:02:59,457   File "C:\Users\Ayobami\anaconda3\envs\new-mask-tut\lib\site-packages\pip\_vendor\urllib3\connectionpool.py", line 828, in urlopen
2023-08-21T18:02:59,457     **response_kw
2023-08-21T18:02:59,457   File "C:\Users\Ayobami\anaconda3\envs\new-mask-tut\lib\site-packages\pip\_vendor\urllib3\connectionpool.py", line 828, in urlopen
2023-08-21T18:02:59,457     **response_kw
2023-08-21T18:02:59,457   File "C:\Users\Ayobami\anaconda3\envs\new-mask-tut\lib\site-packages\pip\_vendor\urllib3\connectionpool.py", line 828, in urlopen
2023-08-21T18:02:59,457     **response_kw
2023-08-21T18:02:59,457   [Previous line repeated 1 more time]
2023-08-21T18:02:59,457   File "C:\Users\Ayobami\anaconda3\envs\new-mask-tut\lib\site-packages\pip\_vendor\urllib3\connectionpool.py", line 790, in urlopen
2023-08-21T18:02:59,457     retries.sleep()
2023-08-21T18:02:59,457   File "C:\Users\Ayobami\anaconda3\envs\new-mask-tut\lib\site-packages\pip\_vendor\urllib3\util\retry.py", line 432, in sleep
2023-08-21T18:02:59,457     self._sleep_backoff()
2023-08-21T18:02:59,457   File "C:\Users\Ayobami\anaconda3\envs\new-mask-tut\lib\site-packages\pip\_vendor\urllib3\util\retry.py", line 416, in _sleep_backoff
2023-08-21T18:02:59,457     time.sleep(backoff)
2023-08-21T18:02:59,457 KeyboardInterrupt
2023-08-21T18:02:59,522 Remote version of pip: 23.2.1
2023-08-21T18:02:59,523 Local version of pip:  22.3.1
2023-08-21T18:02:59,524 Was pip installed by pip? False
2023-08-21T18:02:59,524 Removed build tracker: 'C:\\Users\\Ayobami\\AppData\\Local\\Temp\\pip-build-tracker-r1t813hu'
